Workbook

Sheet Capa
A1: TRADING SYSTEM CONTROL
A3: Sistema de Gestão e Monitorização
A6: Este ficheiro foi criado para gerir o sistema de trading de forma disciplinada.
A8: Componentes do Sistema:
A9: • Dashboard executivo
A10: • Registo diário de resultados
A11: • Controlo de risco e drawdown
A12: • Gestão de ciclos negativos
A13: • Controlo de crescimento da conta
A14: • Planeamento de aumento de lote
A15: • Projeções de crescimento
A16: Utilização recomendada:
... A20: • Rever o sistema no final de cada mês.

Sheet Uso Rápido
A1: GUIA RÁPIDO DE UTILIZAÇÃO
A3: Objetivo
A4: Usar o ficheiro de forma simples, sem erros de preenchimento e sem decisões impulsivas.
A6: ROTINA DIÁRIA (2 min)
A7: • Aba: Registo Diário
A8: • Preencher apenas: Data, Saldo Inicial, Lucro do Dia, Equity Mínima do Dia e Observações.
A9: • Não mexer em: Lucro Acumulado, Recuperação, Estado, Drawdown Diário ($) e Drawdown Diário (%).
A10: • No fim do dia basta registar os valores e fechar.
A12: ROTINA SEMANAL (5 min)
A13: • Aba: Semaforo Semanal
A14: • Preencher: Semana, Saldo Inicial, Saldo Final, Drawdown Máx (%) e Stop 8% (Sim/Não).
A15: • Interpretar: 🟢 saudável | 🟡 atenção | 🔴 rever.
... A30: LEGENDA DE CORES
A31: Amarelo | B31: Campo para preencher | C31: Cinza / Azul | D31: Campo automático / não mexer
A33: REGRAS DE OURO
A34: • Não mexer no setup durante o mês.
A35: • Não aumentar lote antes de target + mês positivo.
A36: • Não adicionar AUDUSD antes de 250$.
A37: • Não adicionar USDCHF antes de 350$.
A38: • Retirar rendimento apenas do lucro, nunca do capital principal.
A39: • Aceitar ciclos negativos como parte normal do sistema.
A41: ROTINA DE 60 SEGUNDOS
A42: • 1. Confirmar AutoTrading ativo e EA sorridente.
A43: • 2. Verificar Experts/Journal para confirmar que não há erros recentes.
A44: • 3. Confirmar se o EA abriu/fechou posições hoje.
A45: • 4. Ver quantas posições estão abertas e se o número é normal.
... A65: • Se tocar no lock: parar o sistema e analisar.

Sheet Config
A1: Painel de Controlo do Sistema
A3: Capital Atual ($) | B3: 242.66
A4: Aporte Mensal ($) | B4: 55
A5: Meta Diária Média ($) | B5: 1.5
A6: Meta Mensal Conservadora ($) | B6: 30
A7: Meta Mensal Boa ($) | B7: 40
A8: Meta Mensal Excelente ($) | B8: 50 | D8: Nota sobre bónus
A9: Último Ciclo Negativo ($) | B9: -23.81 | D9: O bónus pode ser usado para negociar, mas não conta como capital real.
A10: Meta Zona Verde (1.5x ciclo) ($) | B10: =ABS(B9)*1.5 -> 35.715 | D10: Usar Capital Real para risco, drawdown, lote e projeções.
A11: Lote Atual | B11: 0.01 | D11: O bónus funciona como margem/colchão extra, não como dinheiro teu.
A12: Próximo Lote | B12: 0.02
A13: Próximo Target p/ subir lote ($) | B13: 350
A15: Dias de Trading por Mês | B15: 22
A16: Data de Início do Plano | B16: 2026-03-01
A17: Bónus da Corretora ($) | B17: 40
A18: Capital Real (sem bónus) ($) | B18: =B3-B17 -> 202.66

Sheet Manual Operacional
A1: Manual Operacional do Sistema
A3: Objetivo do Sistema
A4: Crescer a conta com disciplina, mantendo risco controlado.
A5: Aceitar ciclos negativos como parte normal da estatística.
A6: Não mexer no setup durante o mês sem motivo estrutural.
A8: Regras Fixas
A9: 1. Aporte no dia 1 de cada mês.
A10: 2. Não subir lote antes de mês positivo e target de capital atingido.
A11: 3. Não adicionar AUDUSD antes de 250$.
A12: 4. Não adicionar USDCHF antes de 350$.
A13: 5. Rever o sistema no fecho semanal, mensal e trimestral.
A15: Significado dos Campos
A16: Aba | B16: Campo | C16: O que significa | D16: Preencher? | E16: Observação
A17: Config | B17: Capital Atual ($) | C17: Saldo atual da conta no momento da revisão. | D17: Sim | E17: Atualizar quando houver mudança real do saldo.
A18: Config | B18: Aporte Mensal ($) | C18: Valor do aporte mensal programado. | D18: Sim | E18: Manter o valor real que colocas todos os meses.
A19: Config | B19: Meta Diária Média ($) | C19: Lucro diário médio usado nas projeções. | D19: Sim | E19: Ajustar só com dados suficientes.
A20: Config | B20: Meta Mensal Conservadora / Boa / Excelente | C20: Referências de desempenho mensal. | D20: Sim | E20: Não alterar por impulso.
A21: Config | B21: Último Ciclo Negativo ($) | C21: Valor do último reset/ciclo negativo fechado. | D21: Sim | E21: Atualizar sempre que existir novo ciclo relevante.
A22: Config | B22: Meta Zona Verde | C22: 1.5x o último ciclo negativo. | D22: Não | E22: Calculado automaticamente.
A23: Config | B23: Lote Atual / Próximo Lote | C23: Lote em uso e próximo degrau previsto. | D23: Sim | E23: Só alterar quando a regra for cumprida.
A24: Config | B24: Próximo Target p/ subir lote ($) | C24: Capital mínimo para avaliar aumento de lote. | D24: Sim | E24: Referência atual para 0.02.
A25: Config | B25: Dias de Trading por Mês / Data de Início do Plano | C25: Inputs usados nas projeções. | D25: Sim | E25: Só alterar se a rotina mudar.
A26: Registo Diário | B26: Data / Saldo Inicial / Lucro do Dia | C26: Base de acompanhamento diário. | D26: Sim | E26: Preencher diariamente.
A27: Registo Diário | B27: Lucro Acumulado / Recuperação / Estado | C27: Indicadores automáticos do mês. | D27: Não | E27: Calculados automaticamente.
... A39: Cenarios Stress | B39: Cenário / Perda / Impacto / Estado | C39: Quadro de referência para stress do sistema. | D39: Não | E39: Automático / referência.
A41: Atualização importante do Registo Diário
A42: Equity Mínima do Dia ($): menor valor da equity observado durante o dia.
A43: Drawdown Diário ($): calculado automaticamente = Saldo Inicial - Equity Mínima.
A44: Drawdown Diário (%): calculado automaticamente = Drawdown Diário / Saldo Inicial.
A46: Tratamento do Bónus da Corretora
A47: Bónus da Corretora ($): valor oferecido pela corretora que pode ser usado para negociar.
A48: Capital Real (sem bónus): saldo total menos o bónus; é este valor que deve contar para risco real.
A49: O bónus deve ser visto como margem/colchão extra e não como capital teu.
A50: Os lucros obtidos com a ajuda do bónus são teus; o bónus em si não deve contar para subida de lote.
A52: Profit Lock
A53: O Profit Lock começa a fazer sentido a partir de 300$.
A54: A regra atual protege 30% do lucro acumulado.
... A56: O Profit Lock evita devolver demasiado lucro ao mercado quando a conta começa a crescer.

Sheet Dashboard
A1: EXECUTIVE DASHBOARD
A3: Capital e Performance | B3: =Config!B3 -> 242.66 | D3: Semáforo do Sistema | J3: Resumo Executivo
A4: Lucro Acumulado Mês ($) | B4: =SUM('Registo Diário'!C2:C101) -> -5.51 | D4: =IF(B4<Config!B10*0.6,"🔴 Abaixo do ideal",IF(B4<Config!B10,"🟡 Em recuperação","🟢 Saudável")) -> 🔴 Abaixo do ideal | J4: Capital Atual | K4: =Config!B3 -> 242.66
A5: Saldo Projetado Fim do Mês ($) | B5: =B3+Config!B6 -> 272.66 | D5: Regra: | E5: Zona verde quando lucro acumulado ≥ 1.5x último ciclo negativo | J5: Lucro Mês | K5: =SUM('Registo Diário'!C2:C101) -> -5.51
A6: Meta Zona Verde ($) | B6: =Config!B10 -> 35.715 | J6: Score Saúde | K6: ='Score de Saude'!B7 -> 55
A7: Próximo Target ($) | B7: =Config!B13 -> 350 | D7: Expansão de Pares | J7: Classificação | K7: ='Score de Saude'!B8 -> Aceitável
A8: Lote Atual | B8: =Config!B11 -> 0.01 | D8: =IF(Config!B3<250,"Manter 3 pares",IF(Config!B3<350,"Pode avaliar AUDUSD","Pode avaliar AUDUSD + USDCHF")) -> Manter 3 pares | J8: Próximo Target | K8: =Config!B13 -> 350
D9: Regra: adicionar pares antes de subir lote | J9: Data Prevista Próx. Target | K9: =Projeções!K5 -> 46113
A10: Saúde do Sistema | D10: Alertas Automáticos | J10: Expansão Pares | K10: =IF(Config!B3<250,"Manter 3 pares",IF(Config!B3<350,"Avaliar AUDUSD","Avaliar AUDUSD + USDCHF")) -> Manter 3 pares
D11: Subida de lote | E11: =IF(Config!B3>=Config!B13,"Rever lote 0.02","Manter lote atual") -> Manter lote atual | J11: Lote | K11: =Config!B11 -> 0.01
D12: Adicionar AUDUSD | E12: =IF(Config!B3>=250,"Pode avaliar AUDUSD","Ainda não") -> Ainda não
D13: Adicionar USDCHF | E13: =IF(Config!B3>=350,"Pode avaliar USDCHF","Ainda não") -> Ainda não
D14: Zona de saúde | E14: =IF(B4<Config!B10*0.6,"Abaixo do ideal",IF(B4<Config!B10,"Em recuperação","Saudável")) -> Abaixo do ideal
D15: Meta mensal | E15: =IF(B20<Config!B6,"🔴",IF(B20<Config!B7,"🟡","🟢")) -> 🔴
A17: Gestão de Risco
A19: Resumo Mensal
A20: Lucro Mês Atual ($) | B20: =SUM('Registo Diário'!C2:C101) -> -5.51
A21: Meta Conservadora ($) | B21: =Config!B6 -> 30
A22: Meta Boa ($) | B22: =Config!B7 -> 40
A23: Meta Excelente ($) | B23: =Config!B8 -> 50
A24: Estado da Meta | B24: =IF(B20<Config!B6,"🔴 Abaixo da meta",IF(B20<Config!B7,"🟡 Meta mínima atingida",IF(B20<Config!B8,"🟢 Meta boa","🚀 Meta excelente"))) -> 🔴 Abaixo da meta
A26: Checklist Rápida | J26: Nota | K26: Campos amarelos = preencher | cinza/azul = não mexer
A27: Não mexer no setup durante o mês | J27: Simulação 10k
A28: Aporte no dia 1 | J28: Meses estimados | K28: ='Simulador 10k'!F5 -> 127.23818
A29: Subir lote só após target + mês positivo | J29: Recomendação de lote | K29: ='Indicador Lote'!B13 -> Manter lote atual
A30: Adicionar AUDUSD só após 250$ | J30: Pode subir 0.02? | K30: ='Indicador Lote'!B10 -> Não
A31: Adicionar USDCHF só após 350$ | J31: Pode subir 0.03? | K31: ='Indicador Lote'!B11 -> Não
A32: Aceitar ciclos negativos como parte do sistema | J32: Pode subir 0.05? | K32: ='Indicador Lote'!B12 -> Não
A33: Bónus Corretora | B33: =Config!B17 -> 40 | J33: Drawdown diário | K33: Automático via Equity Mínima do Dia
A34: Capital Real | B34: =Config!B18 -> 202.66
J35: Drawdown Semanal | K35: ='DD Metrics'!B4 -> 0
J36: Drawdown Mensal | K36: ='DD Metrics'!B5 -> 1.18
J37: Drawdown Histórico | K37: ='DD Metrics'!B6 -> 1.18
J38: Stress do Sistema | K38: ='DD Metrics'!B11 -> 🔴 Stress Elevado
J40: Plano Rendimentos
J41: Fase atual | K41: ='Plano Rendimentos'!B11 -> Acumulação
J42: Retirada sugerida | K42: ='Plano Rendimentos'!B12 -> 0
J43: Retirada mensal estimada | K43: ='Plano Rendimentos'!B13 -> 0
J44: Lucro a reinvestir | K44: ='Plano Rendimentos'!B14 -> 33
J45: Saúde do EA
...

Sheet Registo Diário
A1: Data | B1: Saldo Inicial ($) | C1: Lucro do Dia ($) | D1: Lucro Acumulado do Mês ($) | E1: Recuperação (%) | F1: Estado | G1: Equity Mínima do Dia Corretora ($) | H1: Drawdown Diário ($) | I1: Drawdown Diário (%) | J1: Observações | L1: Métricas Quantitativas
A2: 46083 | B2: 202.66 | C2: 4.72 | D2: =SUM($C$2:C2) -> 4.72 | E2: =IF(Config!$B$9<>0,ABS(D2/Config!$B$9),0) -> 0.19823604 | F2: =IF(E2<0.3,"🔴 Vermelho",IF(E2<0.6,"🟡 Amarelo","🟢 Verde")) -> 🔴 Vermelho | H2: =IF(OR(B2="",G2=""),"",MAX(0,B2-(G2-Config!$B$17))) | I2: =IF(OR(B2="",G2=""),"",MAX(0,(B2-(G2-Config!$B$17))/B2)) | L2: Métrica | M2: Valor | N2: Classificação
A3: 46084 | B3: 207.38 | C3: 1.4 | D3: =SUM($C$2:C3) -> 6.12 | E3: =IF(Config!$B$9<>0,ABS(D3/Config!$B$9),0) -> 0.25703486 | F3: =IF(E3<0.3,"🔴 Vermelho",IF(E3<0.6,"🟡 Amarelo","🟢 Verde")) -> 🔴 Vermelho | H3: =IF(OR(B3="",G3=""),"",MAX(0,B3-(G3-Config!$B$17))) | I3: =IF(OR(B3="",G3=""),"",MAX(0,(B3-(G3-Config!$B$17))/B3)) | L3: Recovery Factor | M3: =IFERROR(MAX($D$2:$D$500)/MAX($H$2:$H$500),"") -> 13.228814 | N3: =IF(M3="","",IF(M3<1,"🔴 Fraco",IF(M3<2,"🟡 Aceitável","🟢 Bom"))) -> 🟢 Bom
A4: 46085 | B4: 208.78 | C4: 1.29 | D4: =SUM($C$2:C4) -> 7.41 | E4: =IF(Config!$B$9<>0,ABS(D4/Config!$B$9),0) -> 0.31121378 | F4: =IF(E4<0.3,"🔴 Vermelho",IF(E4<0.6,"🟡 Amarelo","🟢 Verde")) -> 🟡 Amarelo | H4: =IF(OR(B4="",G4=""),"",MAX(0,B4-(G4-Config!$B$17))) | I4: =IF(OR(B4="",G4=""),"",MAX(0,(B4-(G4-Config!$B$17))/B4)) | L4: Ulcer Index | M4: =IFERROR(SQRT(SUMPRODUCT(($I$2:$I$500<>"")*($I$2:$I$500*$I$2:$I$500))/COUNTIF($I$2:$I$500,"<>")),"") | N4: =IF(M4="","",IF(M4>10%,"🔴 Perigoso",IF(M4>5%,"🟡 Atenção","🟢 Bom")))
A5: 46086 | B5: 210.07 | C5: 1.35 | D5: =SUM($C$2:C5) -> 8.76 | E5: =IF(Config!$B$9<>0,ABS(D5/Config!$B$9),0) -> 0.36791264 | F5: =IF(E5<0.3,"🔴 Vermelho",IF(E5<0.6,"🟡 Amarelo","🟢 Verde")) -> 🟡 Amarelo | H5: =IF(OR(B5="",G5=""),"",MAX(0,B5-(G5-Config!$B$17))) | I5: =IF(OR(B5="",G5=""),"",MAX(0,(B5-(G5-Config!$B$17))/B5)) | L5: MAR Ratio | M5: =IFERROR((((SUM($C$2:$C$500)/MAX($B$2:$B$500))*(365/COUNTIF($A$2:$A$500,"<>")))/MAX($I$2:$I$500)),"") -> -118.05272 | N5: =IF(M5="","",IF(M5<0.5,"🔴 Fraco",IF(M5<1.5,"🟡 Aceitável","🟢 Bom"))) -> 🔴 Fraco
A6: 46087 | B6: 211.42 | C6: 5.33 | D6: =SUM($C$2:C6) -> 14.09 | E6: =IF(Config!$B$9<>0,ABS(D6/Config!$B$9),0) -> 0.59176816 | F6: =IF(E6<0.3,"🔴 Vermelho",IF(E6<0.6,"🟡 Amarelo","🟢 Verde")) -> 🟡 Amarelo | H6: =IF(OR(B6="",G6=""),"",MAX(0,B6-(G6-Config!$B$17))) | I6: =IF(OR(B6="",G6=""),"",MAX(0,(B6-(G6-Config!$B$17))/B6))
A7: 46090 | B7: 216.75 | C7: 1.52 | D7: =SUM($C$2:C7) -> 15.61 | E7: =IF(Config!$B$9<>0,ABS(D7/Config!$B$9),0) -> 0.65560689 | F7: =IF(E7<0.3,"🔴 Vermelho",IF(E7<0.6,"🟡 Amarelo","🟢 Verde")) -> 🟢 Verde | H7: =IF(OR(B7="",G7=""),"",MAX(0,B7-(G7-Config!$B$17))) | I7: =IF(OR(B7="",G7=""),"",MAX(0,(B7-(G7-Config!$B$17))/B7)) | L7: Alerta de Risco | M7: =IF(OR(M3<1,M4>10%,M5<0.5),"🔴 Risco Elevado",IF(OR(M3<2,M4>5%,M5<1.5),"🟡 Risco Moderado","🟢 Risco Controlado")) -> 🔴 Risco Elevado | N7: Monitor automático
A8: 46091 | B8: 218.27 | C8: -23.81 | D8: =SUM($C$2:C8) -> -8.2 | E8: =IF(Config!$B$9<>0,ABS(D8/Config!$B$9),0) -> 0.34439311 | F8: =IF(E8<0.3,"🔴 Vermelho",IF(E8<0.6,"🟡 Amarelo","🟢 Verde")) -> 🟡 Amarelo | H8: =IF(OR(B8="",G8=""),"",MAX(0,B8-(G8-Config!$B$17))) | I8: =IF(OR(B8="",G8=""),"",MAX(0,(B8-(G8-Config!$B$17))/B8)) | J8: 1º Ciclo Negativo
A9: 46092 | B9: 194.46 | C9: 1.05 | D9: =SUM($C$2:C9) -> -7.15 | E9: =IF(Config!$B$9<>0,ABS(D9/Config!$B$9),0) -> 0.30029399 | F9: =IF(E9<0.3,"🔴 Vermelho",IF(E9<0.6,"🟡 Amarelo","🟢 Verde")) -> 🟡 Amarelo | H9: =IF(OR(B9="",G9=""),"",MAX(0,B9-(G9-Config!$B$17))) | I9: =IF(OR(B9="",G9=""),"",MAX(0,(B9-(G9-Config!$B$17))/B9)) | L9: Leitura rápida
A10: 46093 | B10: 195.51 | C10: 1.03 | D10: =SUM($C$2:C10) -> -6.12 | E10: =IF(Config!$B$9<>0,ABS(D10/Config!$B$9),0) -> 0.25703486 | F10: =IF(E10<0.3,"🔴 Vermelho",IF(E10<0.6,"🟡 Amarelo","🟢 Verde")) -> 🔴 Vermelho | G10: 235.42 | H10: =IF(OR(B10="",G10=""),"",MAX(0,B10-(G10-Config!$B$17))) -> 0.09 | I10: =IF(OR(B10="",G10=""),"",MAX(0,(B10-(G10-Config!$B$17))/B10)) -> 0.00046033451 | L10: Recovery alto = melhor
A11: 46094 | B11: 196.54 | C11: 0.61 | D11: =SUM($C$2:C11) -> -5.51 | E11: =IF(Config!$B$9<>0,ABS(D11/Config!$B$9),0) -> 0.23141537 | F11: =IF(E11<0.3,"🔴 Vermelho",IF(E11<0.6,"🟡 Amarelo","🟢 Verde")) -> 🔴 Vermelho | G11: 235.36 | H11: =IF(OR(B11="",G11=""),"",MAX(0,B11-(G11-Config!$B$17))) -> 1.18 | I11: =IF(OR(B11="",G11=""),"",MAX(0,(B11-(G11-Config!$B$17))/B11)) -> 0.0060038669 | L11: Ulcer baixo = melhor
D12: =SUM($C$2:C12) -> -5.51 | E12: =IF(Config!$B$9<>0,ABS(D12/Config!$B$9),0) -> 0.23141537 | F12: =IF(E12<0.3,"🔴 Vermelho",IF(E12<0.6,"🟡 Amarelo","🟢 Verde")) -> 🔴 Vermelho | H12: =IF(OR(B12="",G12=""),"",MAX(0,B12-(G12-Config!$B$17))) | I12: =IF(OR(B12="",G12=""),"",MAX(0,(B12-(G12-Config!$B$17))/B12)) | L12: MAR alto = melhor
D13: =SUM($C$2:C13) -> -5.51 | E13: =IF(Config!$B$9<>0,ABS(D13/Config!$B$9),0) -> 0.23141537 | F13: =IF(E13<0.3,"🔴 Vermelho",IF(E13<0.6,"🟡 Amarelo","🟢 Verde")) -> 🔴 Vermelho | H13: =IF(OR(B13="",G13=""),"",MAX(0,B13-(G13-Config!$B$17))) | I13: =IF(OR(B13="",G13=""),"",MAX(0,(B13-(G13-Config!$B$17))/B13)) | L13: Risco Elevado = rever sistema
D14: =SUM($C$2:C14) -> -5.51 | E14: =IF(Config!$B$9<>0,ABS(D14/Config!$B$9),0) -> 0.23141537 | F14: =IF(E14<0.3,"🔴 Vermelho",IF(E14<0.6,"🟡 Amarelo","🟢 Verde")) -> 🔴 Vermelho | H14: =IF(OR(B14="",G14=""),"",MAX(0,B14-(G14-Config!$B$17))) | I14: =IF(OR(B14="",G14=""),"",MAX(0,(B14-(G14-Config!$B$17))/B14))
D15: =SUM($C$2:C15) -> -5.51 | E15: =IF(Config!$B$9<>0,ABS(D15/Config!$B$9),0) -> 0.23141537 | F15: =IF(E15<0.3,"🔴 Vermelho",IF(E15<0.6,"🟡 Amarelo","🟢 Verde")) -> 🔴 Vermelho | H15: =IF(OR(B15="",G15=""),"",MAX(0,B15-(G15-Config!$B$17))) | I15: =IF(OR(B15="",G15=""),"",MAX(0,(B15-(G15-Config!$B$17))/B15))
D16: =SUM($C$2:C16) -> -5.51 | E16: =IF(Config!$B$9<>0,ABS(D16/Config!$B$9),0) -> 0.23141537 | F16: =IF(E16<0.3,"🔴 Vermelho",IF(E16<0.6,"🟡 Amarelo","🟢 Verde")) -> 🔴 Vermelho | H16: =IF(OR(B16="",G16=""),"",MAX(0,B16-(G16-Config!$B$17))) | I16: =IF(OR(B16="",G16=""),"",MAX(0,(B16-(G16-Config!$B$17))/B16))
D17: =SUM($C$2:C17) -> -5.51 | E17: =IF(Config!$B$9<>0,ABS(D17/Config!$B$9),0) -> 0.23141537 | F17: =IF(E17<0.3,"🔴 Vermelho",IF(E17<0.6,"🟡 Amarelo","🟢 Verde")) -> 🔴 Vermelho | H17: =IF(OR(B17="",G17=""),"",MAX(0,B17-(G17-Config!$B$17))) | I17: =IF(OR(B17="",G17=""),"",MAX(0,(B17-(G17-Config!$B$17))/B17))
D18: =SUM($C$2:C18) -> -5.51 | E18: =IF(Config!$B$9<>0,ABS(D18/Config!$B$9),0) -> 0.23141537 | F18: =IF(E18<0.3,"🔴 Vermelho",IF(E18<0.6,"🟡 Amarelo","🟢 Verde")) -> 🔴 Vermelho | H18: =IF(OR(B18="",G18=""),"",MAX(0,B18-(G18-Config!$B$17))) | I18: =IF(OR(B18="",G18=""),"",MAX(0,(B18-(G18-Config!$B$17))/B18))
D19: =SUM($C$2:C19) -> -5.51 | E19: =IF(Config!$B$9<>0,ABS(D19/Config!$B$9),0) -> 0.23141537 | F19: =IF(E19<0.3,"🔴 Vermelho",IF(E19<0.6,"🟡 Amarelo","🟢 Verde")) -> 🔴 Vermelho | H19: =IF(OR(B19="",G19=""),"",MAX(0,B19-(G19-Config!$B$17))) | I19: =IF(OR(B19="",G19=""),"",MAX(0,(B19-(G19-Config!$B$17))/B19))
D20: =SUM($C$2:C20) -> -5.51 | E20: =IF(Config!$B$9<>0,ABS(D20/Config!$B$9),0) -> 0.23141537 | F20: =IF(E20<0.3,"🔴 Vermelho",IF(E20<0.6,"🟡 Amarelo","🟢 Verde")) -> 🔴 Vermelho | H20: =IF(OR(B20="",G20=""),"",MAX(0,B20-(G20-Config!$B$17))) | I20: =IF(OR(B20="",G20=""),"",MAX(0,(B20-(G20-Config!$B$17))/B20))
D21: =SUM($C$2:C21) -> -5.51 | E21: =IF(Config!$B$9<>0,ABS(D21/Config!$B$9),0) -> 0.23141537 | F21: =IF(E21<0.3,"🔴 Vermelho",IF(E21<0.6,"🟡 Amarelo","🟢 Verde")) -> 🔴 Vermelho | H21: =IF(OR(B21="",G21=""),"",MAX(0,B21-(G21-Config!$B$17))) | I21: =IF(OR(B21="",G21=""),"",MAX(0,(B21-(G21-Config!$B$17))/B21))
D22: =SUM($C$2:C22) -> -5.51 | E22: =IF(Config!$B$9<>0,ABS(D22/Config!$B$9),0) -> 0.23141537 | F22: =IF(E22<0.3,"🔴 Vermelho",IF(E22<0.6,"🟡 Amarelo","🟢 Verde")) -> 🔴 Vermelho | H22: =IF(OR(B22="",G22=""),"",MAX(0,B22-(G22-Config!$B$17))) | I22: =IF(OR(B22="",G22=""),"",MAX(0,(B22-(G22-Config!$B$17))/B22))
D23: =SUM($C$2:C23) -> -5.51 | E23: =IF(Config!$B$9<>0,ABS(D23/Config!$B$9),0) -> 0.23141537 | F23: =IF(E23<0.3,"🔴 Vermelho",IF(E23<0.6,"🟡 Amarelo","🟢 Verde")) -> 🔴 Vermelho | H23: =IF(OR(B23="",G23=""),"",MAX(0,B23-(G23-Config!$B$17))) | I23: =IF(OR(B23="",G23=""),"",MAX(0,(B23-(G23-Config!$B$17))/B23))
D24: =SUM($C$2:C24) -> -5.51 | E24: =IF(Config!$B$9<>0,ABS(D24/Config!$B$9),0) -> 0.23141537 | F24: =IF(E24<0.3,"🔴 Vermelho",IF(E24<0.6,"🟡 Amarelo","🟢 Verde")) -> 🔴 Vermelho | H24: =IF(OR(B24="",G24=""),"",MAX(0,B24-(G24-Config!$B$17))) | I24: =IF(OR(B24="",G24=""),"",MAX(0,(B24-(G24-Config!$B$17))/B24))
D25: =SUM($C$2:C25) -> -5.51 | E25: =IF(Config!$B$9<>0,ABS(D25/Config!$B$9),0) -> 0.23141537 | F25: =IF(E25<0.3,"🔴 Vermelho",IF(E25<0.6,"🟡 Amarelo","🟢 Verde")) -> 🔴 Vermelho | H25: =IF(OR(B25="",G25=""),"",MAX(0,B25-(G25-Config!$B$17))) | I25: =IF(OR(B25="",G25=""),"",MAX(0,(B25-(G25-Config!$B$17))/B25))
... D101: =SUM($C$2:C101) -> -5.51 | E101: =IF(Config!$B$9<>0,ABS(D101/Config!$B$9),0) -> 0.23141537 | F101: =IF(E101<0.3,"🔴 Vermelho",IF(E101<0.6,"🟡 Amarelo","🟢 Verde")) -> 🔴 Vermelho | H101: =IF(OR(B101="",G101=""),"",MAX(0,B101-(G101-Config!$B$17))) | I101: =IF(OR(B101="",G101=""),"",MAX(0,(B101-(G101-Config!$B$17))/B101))
A104: Novo preenchimento diário:
A105: Preencher apenas: Data, Saldo Inicial, Lucro do Dia, Equity Mínima do Dia e Observações.
A106: O Drawdown Diário ($) e o Drawdown Diário (%) são automáticos.

Sheet Semaforo Semanal
A1: Semáforo Semanal do Sistema
A3: Semana | B3: Saldo Inicial ($) | C3: Saldo Final ($) | D3: Lucro/Prejuízo ($) | E3: % Semana | F3: Drawdown Máx (%) | G3: Stop 8%? | H3: Semáforo
A4: 46083 | B4: 202.66 | C4: 216.75 | D4: =IF(OR(B4="",C4=""),"",C4-B4) -> 14.09 | E4: =IF(B4>0,D4/B4,"") -> 0.069525313 | G4: Não | H4: =IF(OR(E4="",F4=""),"",IF(OR(F4>0.08,G4="Sim"),"🔴 Rever",IF(E4<0,"🟡 Atenção","🟢 Saudável")))
A5: 46090 | B5: 216.75 | C5: 197.15 | D5: =IF(OR(B5="",C5=""),"",C5-B5) -> -19.6 | E5: =IF(B5>0,D5/B5,"") -> -0.090426759 | F5: 0.006 | G5: Sim | H5: =IF(OR(E5="",F5=""),"",IF(OR(F5>0.08,G5="Sim"),"🔴 Rever",IF(E5<0,"🟡 Atenção","🟢 Saudável"))) -> 🔴 Rever
D6: =IF(OR(B6="",C6=""),"",C6-B6) | E6: =IF(B6>0,D6/B6,"") | H6: =IF(OR(E6="",F6=""),"",IF(OR(F6>0.08,G6="Sim"),"🔴 Rever",IF(E6<0,"🟡 Atenção","🟢 Saudável")))
D7: =IF(OR(B7="",C7=""),"",C7-B7) | E7: =IF(B7>0,D7/B7,"") | H7: =IF(OR(E7="",F7=""),"",IF(OR(F7>0.08,G7="Sim"),"🔴 Rever",IF(E7<0,"🟡 Atenção","🟢 Saudável")))
D8: =IF(OR(B8="",C8=""),"",C8-B8) | E8: =IF(B8>0,D8/B8,"") | H8: =IF(OR(E8="",F8=""),"",IF(OR(F8>0.08,G8="Sim"),"🔴 Rever",IF(E8<0,"🟡 Atenção","🟢 Saudável")))
D9: =IF(OR(B9="",C9=""),"",C9-B9) | E9: =IF(B9>0,D9/B9,"") | H9: =IF(OR(E9="",F9=""),"",IF(OR(F9>0.08,G9="Sim"),"🔴 Rever",IF(E9<0,"🟡 Atenção","🟢 Saudável")))
D10: =IF(OR(B10="",C10=""),"",C10-B10) | E10: =IF(B10>0,D10/B10,"") | H10: =IF(OR(E10="",F10=""),"",IF(OR(F10>0.08,G10="Sim"),"🔴 Rever",IF(E10<0,"🟡 Atenção","🟢 Saudável")))
D11: =IF(OR(B11="",C11=""),"",C11-B11) | E11: =IF(B11>0,D11/B11,"") | H11: =IF(OR(E11="",F11=""),"",IF(OR(F11>0.08,G11="Sim"),"🔴 Rever",IF(E11<0,"🟡 Atenção","🟢 Saudável")))
D12: =IF(OR(B12="",C12=""),"",C12-B12) | E12: =IF(B12>0,D12/B12,"") | H12: =IF(OR(E12="",F12=""),"",IF(OR(F12>0.08,G12="Sim"),"🔴 Rever",IF(E12<0,"🟡 Atenção","🟢 Saudável")))
D13: =IF(OR(B13="",C13=""),"",C13-B13) | E13: =IF(B13>0,D13/B13,"") | H13: =IF(OR(E13="",F13=""),"",IF(OR(F13>0.08,G13="Sim"),"🔴 Rever",IF(E13<0,"🟡 Atenção","🟢 Saudável")))
D14: =IF(OR(B14="",C14=""),"",C14-B14) | E14: =IF(B14>0,D14/B14,"") | H14: =IF(OR(E14="",F14=""),"",IF(OR(F14>0.08,G14="Sim"),"🔴 Rever",IF(E14<0,"🟡 Atenção","🟢 Saudável")))
D15: =IF(OR(B15="",C15=""),"",C15-B15) | E15: =IF(B15>0,D15/B15,"") | H15: =IF(OR(E15="",F15=""),"",IF(OR(F15>0.08,G15="Sim"),"🔴 Rever",IF(E15<0,"🟡 Atenção","🟢 Saudável")))
D16: =IF(OR(B16="",C16=""),"",C16-B16) | E16: =IF(B16>0,D16/B16,"") | H16: =IF(OR(E16="",F16=""),"",IF(OR(F16>0.08,G16="Sim"),"🔴 Rever",IF(E16<0,"🟡 Atenção","🟢 Saudável")))
D17: =IF(OR(B17="",C17=""),"",C17-B17) | E17: =IF(B17>0,D17/B17,"") | H17: =IF(OR(E17="",F17=""),"",IF(OR(F17>0.08,G17="Sim"),"🔴 Rever",IF(E17<0,"🟡 Atenção","🟢 Saudável")))
... D55: =IF(OR(B55="",C55=""),"",C55-B55) | E55: =IF(B55>0,D55/B55,"") | H55: =IF(OR(E55="",F55=""),"",IF(OR(F55>0.08,G55="Sim"),"🔴 Rever",IF(E55<0,"🟡 Atenção","🟢 Saudável")))

Sheet Controlo Mensal
A1: Controlo Mensal e Revisão do Sistema
A3: Mês | B3: Saldo Inicial ($) | C3: Aporte ($) | D3: Lucro do Mês ($) | E3: Saldo Final ($) | F3: ROI do Mês (%) | G3: Drawdown Máx ($) | H3: Drawdown Máx (%) | I3: Ciclo Negativo? (S/N) | J3: Observações
A4: 46082 | B4: 202.66 | C4: 0 | E4: =B4+C4+D4 -> 202.66 | F4: =IF((B4+C4)>0,D4/(B4+C4),0) -> 0 | H4: =IF(E4>0,G4/E4,0) -> 0 | I4: Sim
E5: =B5+C5+D5 -> 0 | F5: =IF((B5+C5)>0,D5/(B5+C5),0) -> 0 | H5: =IF(E5>0,G5/E5,0) -> 0
E6: =B6+C6+D6 -> 0 | F6: =IF((B6+C6)>0,D6/(B6+C6),0) -> 0 | H6: =IF(E6>0,G6/E6,0) -> 0
E7: =B7+C7+D7 -> 0 | F7: =IF((B7+C7)>0,D7/(B7+C7),0) -> 0 | H7: =IF(E7>0,G7/E7,0) -> 0
E8: =B8+C8+D8 -> 0 | F8: =IF((B8+C8)>0,D8/(B8+C8),0) -> 0 | H8: =IF(E8>0,G8/E8,0) -> 0
E9: =B9+C9+D9 -> 0 | F9: =IF((B9+C9)>0,D9/(B9+C9),0) -> 0 | H9: =IF(E9>0,G9/E9,0) -> 0
E10: =B10+C10+D10 -> 0 | F10: =IF((B10+C10)>0,D10/(B10+C10),0) -> 0 | H10: =IF(E10>0,G10/E10,0) -> 0
E11: =B11+C11+D11 -> 0 | F11: =IF((B11+C11)>0,D11/(B11+C11),0) -> 0 | H11: =IF(E11>0,G11/E11,0) -> 0
E12: =B12+C12+D12 -> 0 | F12: =IF((B12+C12)>0,D12/(B12+C12),0) -> 0 | H12: =IF(E12>0,G12/E12,0) -> 0
E13: =B13+C13+D13 -> 0 | F13: =IF((B13+C13)>0,D13/(B13+C13),0) -> 0 | H13: =IF(E13>0,G13/E13,0) -> 0
E14: =B14+C14+D14 -> 0 | F14: =IF((B14+C14)>0,D14/(B14+C14),0) -> 0 | H14: =IF(E14>0,G14/E14,0) -> 0
E15: =B15+C15+D15 -> 0 | F15: =IF((B15+C15)>0,D15/(B15+C15),0) -> 0 | H15: =IF(E15>0,G15/E15,0) -> 0

Sheet Revisao Trimestral
A1: Revisao Trimestral
A3: Trimestre | B3: Capital Inicial ($) | C3: Capital Final ($) | D3: Lucro Total ($) | E3: ROI (%) | F3: Máx DD ($) | G3: Máx DD (%) | H3: Ciclos Negativos | I3: Decisão | J3: Observações
A4: JAN-MAR 26 | B4: 202.66 | D4: =IF(OR(B4="",C4=""),"",C4-B4) | E4: =IF(B4>0,D4/B4,"") -> #VALUE! | F4: 1.18 | G4: 0.006 | H4: 1
D5: =IF(OR(B5="",C5=""),"",C5-B5) | E5: =IF(B5>0,D5/B5,"") | G5: =IF(C5>0,F5/C5,"")
D6: =IF(OR(B6="",C6=""),"",C6-B6) | E6: =IF(B6>0,D6/B6,"") | G6: =IF(C6>0,F6/C6,"")
D7: =IF(OR(B7="",C7=""),"",C7-B7) | E7: =IF(B7>0,D7/B7,"") | G7: =IF(C7>0,F7/C7,"")
D8: =IF(OR(B8="",C8=""),"",C8-B8) | E8: =IF(B8>0,D8/B8,"") | G8: =IF(C8>0,F8/C8,"")
D9: =IF(OR(B9="",C9=""),"",C9-B9) | E9: =IF(B9>0,D9/B9,"") | G9: =IF(C9>0,F9/C9,"")
D10: =IF(OR(B10="",C10=""),"",C10-B10) | E10: =IF(B10>0,D10/B10,"") | G10: =IF(C10>0,F10/C10,"")
D11: =IF(OR(B11="",C11=""),"",C11-B11) | E11: =IF(B11>0,D11/B11,"") | G11: =IF(C11>0,F11/C11,"")
D12: =IF(OR(B12="",C12=""),"",C12-B12) | E12: =IF(B12>0,D12/B12,"") | G12: =IF(C12>0,F12/C12,"")
D13: =IF(OR(B13="",C13=""),"",C13-B13) | E13: =IF(B13>0,D13/B13,"") | G13: =IF(C13>0,F13/C13,"")
D14: =IF(OR(B14="",C14=""),"",C14-B14) | E14: =IF(B14>0,D14/B14,"") | G14: =IF(C14>0,F14/C14,"")
D15: =IF(OR(B15="",C15=""),"",C15-B15) | E15: =IF(B15>0,D15/B15,"") | G15: =IF(C15>0,F15/C15,"")
D16: =IF(OR(B16="",C16=""),"",C16-B16) | E16: =IF(B16>0,D16/B16,"") | G16: =IF(C16>0,F16/C16,"")
... D20: =IF(OR(B20="",C20=""),"",C20-B20) | E20: =IF(B20>0,D20/B20,"") | G20: =IF(C20>0,F20/C20,"")

Sheet Controlo Lote
A1: Plano de Escala de Lote
A3: Faixa de Saldo ($) | B3: Lote Recomendado | C3: Pode Aplicar? | D3: Data Atingido | E3: Observação
A4: 150 - 350 | B4: 0.01 | C4: =IF(Config!B3>=150,"Sim","Não") -> Sim | E4: Fase atual
A5: 350 - 700 | B5: 0.02 | C5: =IF(Config!B3>=350,"Sim","Não") -> Não | E5: Só após mês positivo
A6: 700 - 1200 | B6: 0.03 | C6: =IF(Config!B3>=700,"Sim","Não") -> Não | E6: Escala progressiva
A7: 1200 - 2000 | B7: 0.05 | C7: =IF(Config!B3>=1200,"Sim","Não") -> Não | E7: Manter disciplina

Sheet Targets
A1: Target | B1: Capital Alvo ($) | C1: Meta Semanal ($) | D1: Observação | E1: Atingido?
A2: Próximo Marco | B2: 250 | C2: 2.5 | D2: Adicionar 4.º par só após estabilidade | E2: =IF(Config!B3>=250,"Sim","Não") -> Não
A3: Subida de Lote | B3: 350 | C3: 3 | D3: Avaliar 0.02 apenas após mês positivo | E3: =IF(Config!B3>=350,"Sim","Não") -> Não
A4: Consolidação | B4: 500 | C4: 4 | D4: Sistema mais confortável | E4: =IF(Config!B3>=500,"Sim","Não") -> Não
A5: Escala | B5: 700 | C5: 5 | D5: Possível lote 0.03 | E5: =IF(Config!B3>=700,"Sim","Não") -> Não
A6: Objetivo 1 | B6: 1000 | C6: 6 | D6: Conta com robustez relevante | E6: =IF(Config!B3>=1000,"Sim","Não") -> Não
A9: Expansão de Pares
A10: Fase | B10: Capital Mínimo ($) | C10: Par a Adicionar | D10: Condição | E10: Estado
A11: Fase 1 | B11: 250 | C11: AUDUSD | D11: Adicionar só após estabilidade e sem mexer no lote | E11: =IF(Config!B3>=250,"Pode avaliar","Aguardar") -> Aguardar
A12: Fase 2 | B12: 350 | C12: USDCHF | D12: Adicionar apenas após mês positivo e conta estável | E12: =IF(Config!B3>=350,"Pode avaliar","Aguardar") -> Aguardar

Sheet Projeções
A1: Projeções Automáticas do Sistema
A3: Capital Atual ($) | B3: =Config!B18 -> 202.66 | D3: Estimativa de datas para targets | I3: Data Prevista dos Targets
A4: Aporte Mensal ($) | B4: =Config!B4 -> 55 | D4: Target ($) | E4: Défice ($) | F4: Meses Estimados | G4: Comentário | I4: Target ($) | J4: Meses Estimados | K4: Data Prevista
A5: Lucro Médio Diário ($) | B5: =Config!B5 -> 1.5 | D5: 250 | E5: =MAX(D5-$B$3,0) -> 47.34 | F5: =IF(($B$7+$B$4)>0,E5/($B$7+$B$4),0) -> 0.53795455 | G5: =IF(E5=0,"Target já atingido",IF(F5<1,"Menos de 1 mês",ROUNDUP(F5,0)&" mês(es)")) -> Menos de 1 mês | I5: =D5 -> 250 | J5: =F5 -> 0.53795455 | K5: =IF(OR(J5="",Config!B16=""),"",EDATE(DATEVALUE(Config!B16),ROUNDUP(J5,0))) -> 46113
A6: Dias de Trading/Mês | B6: =Config!B15 -> 22 | D6: 350 | E6: =MAX(D6-$B$3,0) -> 147.34 | F6: =IF(($B$7+$B$4)>0,E6/($B$7+$B$4),0) -> 1.6743182 | G6: =IF(E6=0,"Target já atingido",IF(F6<1,"Menos de 1 mês",ROUNDUP(F6,0)&" mês(es)")) -> 2 mês(es) | I6: =D6 -> 350 | J6: =F6 -> 1.6743182 | K6: =IF(OR(J6="",Config!B16=""),"",EDATE(DATEVALUE(Config!B16),ROUNDUP(J6,0))) -> 46143
A7: Lucro Médio Mensal ($) | B7: =B5*B6 -> 33 | D7: 500 | E7: =MAX(D7-$B$3,0) -> 297.34 | F7: =IF(($B$7+$B$4)>0,E7/($B$7+$B$4),0) -> 3.3788636 | G7: =IF(E7=0,"Target já atingido",IF(F7<1,"Menos de 1 mês",ROUNDUP(F7,0)&" mês(es)")) -> 4 mês(es) | I7: =D7 -> 500 | J7: =F7 -> 3.3788636 | K7: =IF(OR(J7="",Config!B16=""),"",EDATE(DATEVALUE(Config!B16),ROUNDUP(J7,0))) -> 46204
D8: 700 | E8: =MAX(D8-$B$3,0) -> 497.34 | F8: =IF(($B$7+$B$4)>0,E8/($B$7+$B$4),0) -> 5.6515909 | G8: =IF(E8=0,"Target já atingido",IF(F8<1,"Menos de 1 mês",ROUNDUP(F8,0)&" mês(es)")) -> 6 mês(es) | I8: =D8 -> 700 | J8: =F8 -> 5.6515909 | K8: =IF(OR(J8="",Config!B16=""),"",EDATE(DATEVALUE(Config!B16),ROUNDUP(J8,0))) -> 46266
D9: 1000 | E9: =MAX(D9-$B$3,0) -> 797.34 | F9: =IF(($B$7+$B$4)>0,E9/($B$7+$B$4),0) -> 9.0606818 | G9: =IF(E9=0,"Target já atingido",IF(F9<1,"Menos de 1 mês",ROUNDUP(F9,0)&" mês(es)")) -> 10 mês(es) | I9: =D9 -> 1000 | J9: =F9 -> 9.0606818 | K9: =IF(OR(J9="",Config!B16=""),"",EDATE(DATEVALUE(Config!B16),ROUNDUP(J9,0))) -> 46388
A10: Simulação 12 meses
A11: Mês | B11: Saldo Inicial ($) | C11: Aporte ($) | D11: Lucro Estimado ($) | E11: Saldo Final ($)
A12: 1 | B12: =B3 -> 202.66 | C12: =B4 -> 55 | D12: =B7 -> 33 | E12: =B12+C12+D12 -> 290.66
A13: 2 | B13: =E12 -> 290.66 | C13: =B4 -> 55 | D13: =B7 -> 33 | E13: =B13+C13+D13 -> 378.66
A14: 3 | B14: =E13 -> 378.66 | C14: =B4 -> 55 | D14: =B7 -> 33 | E14: =B14+C14+D14 -> 466.66
A15: 4 | B15: =E14 -> 466.66 | C15: =B4 -> 55 | D15: =B7 -> 33 | E15: =B15+C15+D15 -> 554.66
A16: 5 | B16: =E15 -> 554.66 | C16: =B4 -> 55 | D16: =B7 -> 33 | E16: =B16+C16+D16 -> 642.66
A17: 6 | B17: =E16 -> 642.66 | C17: =B4 -> 55 | D17: =B7 -> 33 | E17: =B17+C17+D17 -> 730.66
A18: 7 | B18: =E17 -> 730.66 | C18: =B4 -> 55 | D18: =B7 -> 33 | E18: =B18+C18+D18 -> 818.66
A19: 8 | B19: =E18 -> 818.66 | C19: =B4 -> 55 | D19: =B7 -> 33 | E19: =B19+C19+D19 -> 906.66
A20: 9 | B20: =E19 -> 906.66 | C20: =B4 -> 55 | D20: =B7 -> 33 | E20: =B20+C20+D20 -> 994.66
A21: 10 | B21: =E20 -> 994.66 | C21: =B4 -> 55 | D21: =B7 -> 33 | E21: =B21+C21+D21 -> 1082.66
A22: 11 | B22: =E21 -> 1082.66 | C22: =B4 -> 55 | D22: =B7 -> 33 | E22: =B22+C22+D22 -> 1170.66
A23: 12 | B23: =E22 -> 1170.66 | C23: =B4 -> 55 | D23: =B7 -> 33 | E23: =B23+C23+D23 -> 1258.66

Sheet Ciclos Negativos
A1: Registo de Ciclos Negativos
A3: Data | B3: Par(es) Afetado(s) | C3: Perda do Ciclo ($) | D3: Drawdown Máx ($) | E3: Nº Máx Posições | F3: Capital no Momento ($) | G3: Peso do Ciclo (%) | H3: Notas
A4: 2026-03 | B4: EURUSD / GBPUSD | C4: -23.81 | D4: 25 | E4: 6 | F4: 218.27 | G4: =ABS(C4/F4) -> 0.10908508 | H4: Primeiro reset de proteção observado.

Sheet Equity vs Drawdown
A1: Equity vs Drawdown
A3: Data | B3: Saldo ($) | C3: Equity ($) | D3: Drawdown ($) | E3: Drawdown (%) | F3: Observação
D4: =IF(OR(B4="",C4=""),"",B4-C4) | E4: =IF(OR(B4="",D4=""),"",D4/B4)
D5: =IF(OR(B5="",C5=""),"",B5-C5) | E5: =IF(OR(B5="",D5=""),"",D5/B5)
D6: =IF(OR(B6="",C6=""),"",B6-C6) | E6: =IF(OR(B6="",D6=""),"",D6/B6)
D7: =IF(OR(B7="",C7=""),"",B7-C7) | E7: =IF(OR(B7="",D7=""),"",D7/B7)
D8: =IF(OR(B8="",C8=""),"",B8-C8) | E8: =IF(OR(B8="",D8=""),"",D8/B8)
D9: =IF(OR(B9="",C9=""),"",B9-C9) | E9: =IF(OR(B9="",D9=""),"",D9/B9)
D10: =IF(OR(B10="",C10=""),"",B10-C10) | E10: =IF(OR(B10="",D10=""),"",D10/B10)
D11: =IF(OR(B11="",C11=""),"",B11-C11) | E11: =IF(OR(B11="",D11=""),"",D11/B11)
D12: =IF(OR(B12="",C12=""),"",B12-C12) | E12: =IF(OR(B12="",D12=""),"",D12/B12)
D13: =IF(OR(B13="",C13=""),"",B13-C13) | E13: =IF(OR(B13="",D13=""),"",D13/B13)
D14: =IF(OR(B14="",C14=""),"",B14-C14) | E14: =IF(OR(B14="",D14=""),"",D14/B14)
D15: =IF(OR(B15="",C15=""),"",B15-C15) | E15: =IF(OR(B15="",D15=""),"",D15/B15)
... D103: =IF(OR(B103="",C103=""),"",B103-C103) | E103: =IF(OR(B103="",D103=""),"",D103/B103)

Sheet Score de Saude
A1: Score de Saúde do Sistema
A2: Lucro Mensal Atual ($) | B2: =SUM('Registo Diário'!C2:C101) -> -5.51 | D2: Leitura do Score
A3: Meta Zona Verde ($) | B3: =Config!B10 -> 35.715 | D3: 85+ = sistema muito saudável
A4: Drawdown Máx Registado ($) | B4: =MAX('Equity vs Drawdown'!D4:D103) -> 0 | D4: 70-84 = sistema bom
A5: Drawdown Máx (%) | B5: =IF(Config!B18>0,MAX('Equity vs Drawdown'!D4:D103)/Config!B18,"") -> 0 | D5: 55-69 = sistema aceitável
A6: Último Ciclo Negativo ($) | B6: =ABS(Config!B9) -> 23.81 | D6: <55 = sistema frágil / precisa atenção
A7: Score Base | B7: =IF(B2>=B3,50,IF(B2>=B3*0.6,35,20))+IF(B5<=0.15,25,IF(B5<=0.2,15,5))+IF(B6<=B2,25,10) -> 55
A8: Classificação | B8: =IF(B7>=85,"Excelente",IF(B7>=70,"Boa",IF(B7>=55,"Aceitável","Frágil"))) -> Aceitável

Sheet Historico Decisoes
A1: Historico Decisoes
A3: Data | B3: Tipo de Decisão | C3: Antes | D3: Depois | E3: Motivo | F3: Aprovado por Dados? | G3: Impacto Esperado | H3: Notas

Sheet Cenarios Stress
A1: Cenarios Stress
A3: Cenário | B3: Perda Estimada ($) | C3: Capital Atual ($) | D3: Impacto (%) | E3: Decisão Recomendada | F3: Ação | G3: Estado | H3: Notas
A4: Ciclo igual ao último | B4: =ABS(Config!B9) -> 23.81 | C4: =Config!B3 -> 242.66 | D4: =IF(C4>0,B4/C4,0) -> 0.098120827 | E4: Aceitar | F4: Não mexer | G4: =IF(D4<=0.15,"🟢 Controlado","🟡 Atenção") -> 🟢 Controlado | H4: Referência base
A5: Ciclo 1.5x pior | B5: =ABS(Config!B9)*1.5 -> 35.715 | C5: =Config!B3 -> 242.66 | D5: =IF(C5>0,B5/C5,0) -> 0.14718124 | E5: Aceitar e monitorizar | F5: Sem mudanças imediatas | G5: =IF(D5<=0.2,"🟡 Atenção","🔴 Stress alto") -> 🟡 Atenção | H5: Stress elevado
A6: Dois ciclos seguidos | B6: =ABS(Config!B9)*2 -> 47.62 | C6: =Config!B3 -> 242.66 | D6: =IF(C6>0,B6/C6,0) -> 0.19624165 | E6: Rever no fecho do mês | F6: Não aumentar lote | G6: =IF(D6<=0.25,"🟡 Atenção","🔴 Rever") -> 🟡 Atenção | H6: Condição crítica
A7: Conta em 250$ | B7: =ABS(Config!B9) -> 23.81 | C7: 250 | D7: =IF(C7>0,B7/C7,0) -> 0.09524 | E7: Mais confortável | F7: Pode avaliar AUDUSD | G7: =IF(D7<=0.12,"🟢 Melhor equilíbrio","🟡") -> 🟢 Melhor equilíbrio | H7: Meta intermédia
A8: Conta em 350$ | B8: =ABS(Config!B9) -> 23.81 | C8: 350 | D8: =IF(C8>0,B8/C8,0) -> 0.068028571 | E8: Sistema robusto | F8: Pode avaliar 0.02 | G8: =IF(D8<=0.1,"🟢 Robusto","🟡") -> 🟢 Robusto | H8: Meta para lote

Sheet Simulador 10k
A1: Simulador de Crescimento até 10 000$
A3: Capital Atual ($) | B3: =Config!B18 -> 202.66 | D3: Estimativa até 10 000$
A4: Aporte Mensal ($) | B4: =Config!B4 -> 55 | D4: Objetivo | E4: Défice ($) | F4: Meses Estimados | G4: Comentário
A5: Lucro Médio Diário ($) | B5: =Config!B5 -> 1.5 | D5: =B8 -> 10000 | E5: =MAX(D5-B3,0) -> 9797.34 | F5: =IF((B6+B4)>0,E5/(B6+B4),"") -> 127.23818 | G5: =IF(E5=0,"Objetivo já atingido",ROUNDUP(F5,0)&" mês(es)") -> 128 mês(es)
A6: Dias de Trading por Mês | B6: =Config!B15 -> 22
A7: Lucro Médio Mensal ($) | B7: =B4*B5 -> 82.5
A8: Objetivo Final ($) | B8: 10000
A10: Simulação Longo Prazo
A11: Mês | B11: Saldo Inicial ($) | C11: Aporte ($) | D11: Lucro Estimado ($) | E11: Saldo Final ($) | F11: Meta 10k Atingida?
A12: 1 | B12: =B3 -> 202.66 | C12: =B4 -> 55 | D12: =B6 -> 22 | E12: =B12+C12+D12 -> 279.66 | F12: =IF(E12>=B8,"Sim","Não") -> Não
A13: 2 | B13: =E12 -> 279.66 | C13: =B4 -> 55 | D13: =B6 -> 22 | E13: =B13+C13+D13 -> 356.66 | F13: =IF(E13>=B8,"Sim","Não") -> Não
A14: 3 | B14: =E13 -> 356.66 | C14: =B4 -> 55 | D14: =B6 -> 22 | E14: =B14+C14+D14 -> 433.66 | F14: =IF(E14>=B8,"Sim","Não") -> Não
A15: 4 | B15: =E14 -> 433.66 | C15: =B4 -> 55 | D15: =B6 -> 22 | E15: =B15+C15+D15 -> 510.66 | F15: =IF(E15>=B8,"Sim","Não") -> Não
A16: 5 | B16: =E15 -> 510.66 | C16: =B4 -> 55 | D16: =B6 -> 22 | E16: =B16+C16+D16 -> 587.66 | F16: =IF(E16>=B8,"Sim","Não") -> Não
A17: 6 | B17: =E16 -> 587.66 | C17: =B4 -> 55 | D17: =B6 -> 22 | E17: =B17+C17+D17 -> 664.66 | F17: =IF(E17>=B8,"Sim","Não") -> Não
A18: 7 | B18: =E17 -> 664.66 | C18: =B4 -> 55 | D18: =B6 -> 22 | E18: =B18+C18+D18 -> 741.66 | F18: =IF(E18>=B8,"Sim","Não") -> Não
A19: 8 | B19: =E18 -> 741.66 | C19: =B4 -> 55 | D19: =B6 -> 22 | E19: =B19+C19+D19 -> 818.66 | F19: =IF(E19>=B8,"Sim","Não") -> Não
A20: 9 | B20: =E19 -> 818.66 | C20: =B4 -> 55 | D20: =B6 -> 22 | E20: =B20+C20+D20 -> 895.66 | F20: =IF(E20>=B8,"Sim","Não") -> Não
A21: 10 | B21: =E20 -> 895.66 | C21: =B4 -> 55 | D21: =B6 -> 22 | E21: =B21+C21+D21 -> 972.66 | F21: =IF(E21>=B8,"Sim","Não") -> Não
A22: 11 | B22: =E21 -> 972.66 | C22: =B4 -> 55 | D22: =B6 -> 22 | E22: =B22+C22+D22 -> 1049.66 | F22: =IF(E22>=B8,"Sim","Não") -> Não
A23: 12 | B23: =E22 -> 1049.66 | C23: =B4 -> 55 | D23: =B6 -> 22 | E23: =B23+C23+D23 -> 1126.66 | F23: =IF(E23>=B8,"Sim","Não") -> Não
A24: 13 | B24: =E23 -> 1126.66 | C24: =B4 -> 55 | D24: =B6 -> 22 | E24: =B24+C24+D24 -> 1203.66 | F24: =IF(E24>=B8,"Sim","Não") -> Não
A25: 14 | B25: =E24 -> 1203.66 | C25: =B4 -> 55 | D25: =B6 -> 22 | E25: =B25+C25+D25 -> 1280.66 | F25: =IF(E25>=B8,"Sim","Não") -> Não
A26: 15 | B26: =E25 -> 1280.66 | C26: =B4 -> 55 | D26: =B6 -> 22 | E26: =B26+C26+D26 -> 1357.66 | F26: =IF(E26>=B8,"Sim","Não") -> Não
A27: 16 | B27: =E26 -> 1357.66 | C27: =B4 -> 55 | D27: =B6 -> 22 | E27: =B27+C27+D27 -> 1434.66 | F27: =IF(E27>=B8,"Sim","Não") -> Não
A28: 17 | B28: =E27 -> 1434.66 | C28: =B4 -> 55 | D28: =B6 -> 22 | E28: =B28+C28+D28 -> 1511.66 | F28: =IF(E28>=B8,"Sim","Não") -> Não
A29: 18 | B29: =E28 -> 1511.66 | C29: =B4 -> 55 | D29: =B6 -> 22 | E29: =B29+C29+D29 -> 1588.66 | F29: =IF(E29>=B8,"Sim","Não") -> Não
A30: 19 | B30: =E29 -> 1588.66 | C30: =B4 -> 55 | D30: =B6 -> 22 | E30: =B30+C30+D30 -> 1665.66 | F30: =IF(E30>=B8,"Sim","Não") -> Não
A31: 20 | B31: =E30 -> 1665.66 | C31: =B4 -> 55 | D31: =B6 -> 22 | E31: =B31+C31+D31 -> 1742.66 | F31: =IF(E31>=B8,"Sim","Não") -> Não
A32: 21 | B32: =E31 -> 1742.66 | C32: =B4 -> 55 | D32: =B6 -> 22 | E32: =B32+C32+D32 -> 1819.66 | F32: =IF(E32>=B8,"Sim","Não") -> Não
A33: 22 | B33: =E32 -> 1819.66 | C33: =B4 -> 55 | D33: =B6 -> 22 | E33: =B33+C33+D33 -> 1896.66 | F33: =IF(E33>=B8,"Sim","Não") -> Não
A34: 23 | B34: =E33 -> 1896.66 | C34: =B4 -> 55 | D34: =B6 -> 22 | E34: =B34+C34+D34 -> 1973.66 | F34: =IF(E34>=B8,"Sim","Não") -> Não
A35: 24 | B35: =E34 -> 1973.66 | C35: =B4 -> 55 | D35: =B6 -> 22 | E35: =B35+C35+D35 -> 2050.66 | F35: =IF(E35>=B8,"Sim","Não") -> Não
A36: 25 | B36: =E35 -> 2050.66 | C36: =B4 -> 55 | D36: =B6 -> 22 | E36: =B36+C36+D36 -> 2127.66 | F36: =IF(E36>=B8,"Sim","Não") -> Não
A37: 26 | B37: =E36 -> 2127.66 | C37: =B4 -> 55 | D37: =B6 -> 22 | E37: =B37+C37+D37 -> 2204.66 | F37: =IF(E37>=B8,"Sim","Não") -> Não
A38: 27 | B38: =E37 -> 2204.66 | C38: =B4 -> 55 | D38: =B6 -> 22 | E38: =B38+C38+D38 -> 2281.66 | F38: =IF(E38>=B8,"Sim","Não") -> Não
A39: 28 | B39: =E38 -> 2281.66 | C39: =B4 -> 55 | D39: =B6 -> 22 | E39: =B39+C39+D39 -> 2358.66 | F39: =IF(E39>=B8,"Sim","Não") -> Não
A40: 29 | B40: =E39 -> 2358.66 | C40: =B4 -> 55 | D40: =B6 -> 22 | E40: =B40+C40+D40 -> 2435.66 | F40: =IF(E40>=B8,"Sim","Não") -> Não
A41: 30 | B41: =E40 -> 2435.66 | C41: =B4 -> 55 | D41: =B6 -> 22 | E41: =B41+C41+D41 -> 2512.66 | F41: =IF(E41>=B8,"Sim","Não") -> Não
A42: 31 | B42: =E41 -> 2512.66 | C42: =B4 -> 55 | D42: =B6 -> 22 | E42: =B42+C42+D42 -> 2589.66 | F42: =IF(E42>=B8,"Sim","Não") -> Não
...

Sheet Indicador Lote
A1: Indicador Automático de Subida de Lote
A3: Capital Atual ($) | B3: =Config!B18 -> 202.66 | D3: Lógica
A4: Último Ciclo Negativo ($) | B4: =ABS(Config!B9) -> 23.81 | D4: 0.02 só após 350$, mês positivo e ciclo <=15% da conta
A5: Peso do Último Ciclo (%) | B5: =IF(B3>0,B4/B3,"") -> 0.11748742 | D5: 0.03 só após 700$, mês positivo e ciclo <=12% da conta
A6: Capital Alvo p/ 0.02 ($) | B6: 350 | D6: 0.05 só após 1200$, mês positivo e ciclo <=10% da conta
A7: Capital Alvo p/ 0.03 ($) | B7: 700 | D7: Se a recomendação disser manter, não subir lote.
A8: Capital Alvo p/ 0.05 ($) | B8: 1200
A9: Mês atual está positivo? | B9: =IF(SUM('Registo Diário'!C2:C101)>0,"Sim","Não") -> Não
A10: Pode subir para 0.02? | B10: =IF(AND(B3>=B5,B8="Sim",B4/B3<=0.15),"Sim","Não") -> Não
A11: Pode subir para 0.03? | B11: =IF(AND(B3>=B6,B8="Sim",B4/B3<=0.12),"Sim","Não") -> Não
A12: Pode subir para 0.05? | B12: =IF(AND(B3>=B7,B8="Sim",B4/B3<=0.1),"Sim","Não") -> Não
A13: Recomendação Atual | B13: =IF(B9="Sim","Subir para 0.05",IF(B8="Sim","Subir para 0.03",IF(B7="Sim","Subir para 0.02","Manter lote atual"))) -> Manter lote atual

Sheet DD Metrics
A1: Drawdown Metrics Automáticas
A3: Métrica | B3: Valor | C3: Descrição
A4: Drawdown Máximo da Semana ($) | B4: =MAX('Registo Diário'!H2:H8) -> 0 | C4: Maior drawdown registado nos últimos 7 dias
A5: Drawdown Máximo do Mês ($) | B5: =MAX('Registo Diário'!H2:H101) -> 1.18 | C5: Maior drawdown registado no mês atual
A6: Drawdown Histórico Máximo ($) | B6: =MAX('Registo Diário'!H2:H500) -> 1.18 | C6: Pior drawdown já registado desde o início
A7: Capital Atual ($) | B7: =Config!B18 -> 202.66 | C7: Saldo atual da conta
A8: Drawdown Histórico (%) | B8: =IF(B6>0,B5/B6,0) -> 1 | C8: Percentagem do pior drawdown face ao capital
A10: Indicador de Stress do Sistema
A11: Classificação | B11: =IF(B7<=0.15,"🟢 Normal",IF(B7<=0.2,"🟡 Atenção","🔴 Stress Elevado")) -> 🔴 Stress Elevado
A12: Base de cálculo | B12: Opção B – risco saudável até 15% de drawdown

Sheet Plano Rendimentos
A1: Plano de Rendimento Mensal e Retiradas
A3: Capital Atual ($) | B3: =Config!B18 -> 202.66 | D3: Política de Retiradas
A4: Lucro Médio Diário ($) | B4: =Config!B5 -> 1.5 | D4: Faixa de Capital ($) | E4: Fase | F4: Retirada do lucro | G4: Reinvestimento | H4: Comentário
A5: Dias de Trading/Mês | B5: =Config!B15 -> 22 | D5: 0 - 1 999 | E5: Acumulação | F5: 0% | G5: 100% | H5: Não retirar; foco total em crescimento
A6: Lucro Médio Mensal Estimado ($) | B6: =B4*B5 -> 33 | D6: 2 000 - 4 999 | E6: Rendimento inicial | F6: 20% | G6: 80% | H6: Retirada simbólica, sem travar crescimento
A7: Percentagem máxima de retirada do lucro | B7: 50 | D7: 5 000 - 9 999 | E7: Rendimento parcial | F7: 30% | G7: 70% | H7: Já permite rendimento mensal mais relevante
D8: 10 000+ | E8: Rendimento estruturado | F8: 40% a 50% | G8: 50% a 60% | H8: Pode pagar rendimento e continuar a crescer
A10: Recomendação Atual
A11: Fase atual | B11: =IF(B3<2000,"Acumulação",IF(B3<5000,"Rendimento inicial",IF(B3<10000,"Rendimento parcial","Rendimento estruturado"))) -> Acumulação
A12: Retirada sugerida do lucro | B12: =IF(B3<2000,0,IF(B3<5000,0.2,IF(B3<10000,0.3,0.5))) -> 0
A13: Retirada mensal estimada ($) | B13: =B6*B12 -> 0
A14: Lucro a reinvestir ($) | B14: =B6-B13 -> 33
A15: Regra | B15: ="Só retirar após mês positivo e nunca tocar no capital principal" -> Só retirar após mês positivo e nunca tocar no capital principal
A18: Cenários de Rendimento por Capital
A19: Capital ($) | B19: Lucro 5%/mês ($) | C19: Lucro 8%/mês ($) | D19: Retirada sugerida ($) | E19: Observação
A20: 2000 | B20: =A20*0.05 -> 100 | C20: =A20*0.08 -> 160 | D20: =IF(A20<5000,B20*0.2,IF(A20<10000,C20*0.3,C20*0.5)) -> 20 | E20: Retirar só do lucro, nunca do capital
A21: 5000 | B21: =A21*0.05 -> 250 | C21: =A21*0.08 -> 400 | D21: =IF(A21<5000,B21*0.2,IF(A21<10000,C21*0.3,C21*0.5)) -> 120 | E21: Retirar só do lucro, nunca do capital
A22: 10000 | B22: =A22*0.05 -> 500 | C22: =A22*0.08 -> 800 | D22: =IF(A22<5000,B22*0.2,IF(A22<10000,C22*0.3,C22*0.5)) -> 400 | E22: Retirar só do lucro, nunca do capital

Sheet Monitor Saude EA
A1: Monitor de Saúde do EA
A3: Indicador | B3: Valor | C3: Regra / Leitura
A4: Drawdown histórico máximo ($) | B4: =MAX('Registo Diário'!H2:H101) -> 1.18 | C4: Referência base do sistema
A5: Drawdown médio do mês ($) | B5: =IFERROR(AVERAGEIF('Registo Diário'!H2:H101,">0"),0) -> 0.635 | C5: Stress médio observado
A6: Lucro médio diário ($) | B6: =IFERROR(AVERAGEIF('Registo Diário'!C2:C101,"<>"),0) -> -0.551 | C6: Eficiência média diária
A7: Lucro do mês atual ($) | B7: =SUM('Registo Diário'!C2:C101) -> -5.51 | C7: Produção mensal atual
A8: Ciclos negativos registados | B8: =COUNTIF('Ciclos Negativos'!C4:C29,"<0") -> 1 | C8: Número de resets/ciclos relevantes
A9: Rácio Lucro / DD | B9: =IFERROR(B7/B5,0) -> -8.6771654 | C9: Lucro mensal dividido pelo DD médio
A10: Sinal de Drawdown | B10: =IF(B4<=B5*2,"Normal","Alerta") -> Normal | C10: Se DD atual > 2x média, atenção
A11: Sinal de Ciclos | B11: =IF(B8<=2,"Normal",IF(B8<=3,"Atenção","Crítico")) -> Normal | C11: 3+ ciclos = alerta
A12: Sinal de Lucro Diário | B12: =IF(B6>=Config!B5,"Normal",IF(B6>=Config!B5*0.6,"Atenção","Crítico")) -> Crítico | C12: Queda do edge diário
A13: Classificação Final | B13: =IF(AND(B10="Normal",B11="Normal",B12="Normal"),"🟢 Saudável",IF(OR(B11="Crítico",B12="Crítico"),"🔴 Degradado","🟡 Atenção")) -> 🔴 Degradado | C13: Painel médico do EA

Sheet Profit Lock
A1: Profit Lock Tracker
A3: Indicador | B3: Valor | C3: Descrição | E3: Exemplo
A4: Capital Real Atual ($) | B4: =Config!B18 -> 202.66 | C4: Capital real sem bónus | E4: Saldo | F4: Lucro | G4: Lock 30% | H4: Profit Lock
A5: Lucro Acumulado Atual ($) | B5: =SUM('Registo Diário'!C2:C101) -> -5.51 | C5: Lucro acumulado no período registado | E5: 300 | F5: 30 | G5: 9 | H5: 309
A6: Saldo Máximo de Referência ($) | B6: =MAX(B4,B4+B5) -> 202.66 | C6: Capital real + lucro acumulado máximo de referência | E6: 400 | F6: 80 | G6: 24 | H6: 424
A7: Ativar Profit Lock? | B7: =IF(B4>=300,"Sim","Ainda não") -> Ainda não | C7: Começar a usar a partir de 300$ | E7: 600 | F7: 150 | G7: 45 | H7: 645
A8: Percentagem de Lock | B8: =IF(B7="Sim",0.3,0) -> 0 | C8: 30% do lucro protegido
A9: Lucro Protegido ($) | B9: =B5*B8 -> 0 | C9: Parte do lucro que fica protegida
A10: Profit Lock ($) | B10: =B4+B9 -> 202.66 | C10: Capital mínimo protegido
A11: Distância ao Lock ($) | B11: =Config!B18-B10 -> 0 | C11: Quanto falta até tocar no lock
A12: Alerta Profit Lock | B12: =IF(B7<>"Sim","Informativo",IF(B11<=0,"🛑 Abaixo do Lock",IF(B11<=10,"⚠ Perto do Lock","🟢 Seguro"))) -> Informativo | C12: Ação recomendada
A13: Regra Operacional | B13: ="Se tocar ou quebrar o Profit Lock: parar o sistema e analisar no fecho do dia." -> Se tocar ou quebrar o Profit Lock: parar o sistema e analisar no fecho do dia. | C13: Disciplina de proteção
